Workbook

Sheet Assumptions
A1: KEY PARAMETERS
A2: Pole Price (MXN, FOB farm) | B2: 400
A3: Wastage % | B3: 0.15
A4: Yield yr5 (poles/ha) | B4: 350 | C4: Year 5 first production (25% of mature)
A5: Yield yr6 (poles/ha) | B5: 700 | C5: Year 6 scaling (50% of mature)
A6: Yield yr7+ (BASE: 1,400/ha) | B6: 1400 | C6: ⚠ CONSERVATIVE BASE (range: 1,000-2,000-3,000)
A7: Carbon Credit Rate (USD/ha/yr) | B7: 21
A8: FX Rate (MXN/USD) | B8: 17
A9: Bridge Round (MXN, 2026) | B9: 2000000
A10: Seed Round (MXN, 2028) | B10: 3000000
A11: Major Funding Year | B11: 2028
A12: Mgmt Salary Base (MXN/month) | B12: 50000
A13: Mgmt Salary Growth %/yr | B13: 0.1
A14: Worker Day Rate (MXN) | B14: 450
A15: Supervisor Day Rate (MXN) | B15: 900
A16: Working Days/Month | B16: 26
A17: Seedling Price External (MXN) | B17: 35
A18: Seedling Price Internal (MXN) | B18: 10
... A21: SG&A Growth Rate %/yr | B21: 0.1
A23: OWNERSHIP STRUCTURE
A24: Investor | B24: 0.25
A25: Ofir | B25: 0.15
A26: Rick | B26: 0.2
A27: Juan | B27: 0.2
A28: Diego | B28: 0.2
A30: PLANTING SCHEDULE
A31: Year | B31: New Ha Planted | C31: Cumulative Ha
A32: 2021 | B32: 10 | C32: 10
A33: 2026 | B33: 0 | C33: =C32+B33
A34: 2027 | B34: 15 | C34: =C33+B34
A35: 2028 | B35: 15 | C35: =C34+B35
A36: 2029 | B36: 10 | C36: =C35+B36
A37: 2030 | B37: 30 | C37: =C36+B37
A38: 2031 | B38: 30 | C38: =C37+B38
A39: 2032 | B39: 0 | C39: =C38+B39
A40: 2033 | B40: 0 | C40: =C39+B40
A41: TOTAL | B41: =SUM(B32:B40) | C41: =C39
A43: CAPEX ITEMS
A44: Item | B44: Amount (MXN) | C44: Year
A45: Land Title Regularization | B45: 38000 | C45: 2026
...

Sheet Production
A1: Year | B1: Base 10Ha | C1: 2026 (0 ha) | D1: Plant 2027 (15ha) | E1: Plant 2028 (15ha) | F1: Plant 2029 (10ha) | G1: Plant 2030 (30ha L) | H1: Plant 2031 (30ha L) | J1: Gross Total | K1: Waste | L1: Net Poles
A2: 2026 | B2: =Assumptions!$B$135 | C2: 0 | D2: =IF(-1<5,0,IF(-1=5,Assumptions!$B$4,IF(-1=6,Assumptions!$B$5,Assumptions!$B$6)))*Assumptions!$B$34 | E2: =IF(-2<5,0,IF(-2=5,Assumptions!$B$4,IF(-2=6,Assumptions!$B$5,Assumptions!$B$6)))*Assumptions!$B$35 | F2: =IF(-3<5,0,IF(-3=5,Assumptions!$B$4,IF(-3=6,Assumptions!$B$5,Assumptions!$B$6)))*Assumptions!$B$36 | G2: =IF(-4<5,0,IF(-4=5,Assumptions!$B$4,IF(-4=6,Assumptions!$B$5,Assumptions!$B$6)))*Assumptions!$B$37 | H2: =IF(-5<5,0,IF(-5=5,Assumptions!$B$4,IF(-5=6,Assumptions!$B$5,Assumptions!$B$6)))*Assumptions!$B$38 | J2: =B2+SUM(C2:H2) | K2: =J2*Assumptions!$B$3 | L2: =J2-K2
A3: 2027 | B3: =Assumptions!$B$136 | C3: 0 | D3: =IF(0<5,0,IF(0=5,Assumptions!$B$4,IF(0=6,Assumptions!$B$5,Assumptions!$B$6)))*Assumptions!$B$34 | E3: =IF(-1<5,0,IF(-1=5,Assumptions!$B$4,IF(-1=6,Assumptions!$B$5,Assumptions!$B$6)))*Assumptions!$B$35 | F3: =IF(-2<5,0,IF(-2=5,Assumptions!$B$4,IF(-2=6,Assumptions!$B$5,Assumptions!$B$6)))*Assumptions!$B$36 | G3: =IF(-3<5,0,IF(-3=5,Assumptions!$B$4,IF(-3=6,Assumptions!$B$5,Assumptions!$B$6)))*Assumptions!$B$37 | H3: =IF(-4<5,0,IF(-4=5,Assumptions!$B$4,IF(-4=6,Assumptions!$B$5,Assumptions!$B$6)))*Assumptions!$B$38 | J3: =B3+SUM(C3:H3) | K3: =J3*Assumptions!$B$3 | L3: =J3-K3
A4: 2028 | B4: =Assumptions!$B$137 | C4: 0 | D4: =IF(1<5,0,IF(1=5,Assumptions!$B$4,IF(1=6,Assumptions!$B$5,Assumptions!$B$6)))*Assumptions!$B$34 | E4: =IF(0<5,0,IF(0=5,Assumptions!$B$4,IF(0=6,Assumptions!$B$5,Assumptions!$B$6)))*Assumptions!$B$35 | F4: =IF(-1<5,0,IF(-1=5,Assumptions!$B$4,IF(-1=6,Assumptions!$B$5,Assumptions!$B$6)))*Assumptions!$B$36 | G4: =IF(-2<5,0,IF(-2=5,Assumptions!$B$4,IF(-2=6,Assumptions!$B$5,Assumptions!$B$6)))*Assumptions!$B$37 | H4: =IF(-3<5,0,IF(-3=5,Assumptions!$B$4,IF(-3=6,Assumptions!$B$5,Assumptions!$B$6)))*Assumptions!$B$38 | J4: =B4+SUM(C4:H4) | K4: =J4*Assumptions!$B$3 | L4: =J4-K4
A5: 2029 | B5: =Assumptions!$B$138 | C5: 0 | D5: =IF(2<5,0,IF(2=5,Assumptions!$B$4,IF(2=6,Assumptions!$B$5,Assumptions!$B$6)))*Assumptions!$B$34 | E5: =IF(1<5,0,IF(1=5,Assumptions!$B$4,IF(1=6,Assumptions!$B$5,Assumptions!$B$6)))*Assumptions!$B$35 | F5: =IF(0<5,0,IF(0=5,Assumptions!$B$4,IF(0=6,Assumptions!$B$5,Assumptions!$B$6)))*Assumptions!$B$36 | G5: =IF(-1<5,0,IF(-1=5,Assumptions!$B$4,IF(-1=6,Assumptions!$B$5,Assumptions!$B$6)))*Assumptions!$B$37 | H5: =IF(-2<5,0,IF(-2=5,Assumptions!$B$4,IF(-2=6,Assumptions!$B$5,Assumptions!$B$6)))*Assumptions!$B$38 | J5: =B5+SUM(C5:H5) | K5: =J5*Assumptions!$B$3 | L5: =J5-K5
A6: 2030 | B6: =Assumptions!$B$139 | C6: 0 | D6: =IF(3<5,0,IF(3=5,Assumptions!$B$4,IF(3=6,Assumptions!$B$5,Assumptions!$B$6)))*Assumptions!$B$34 | E6: =IF(2<5,0,IF(2=5,Assumptions!$B$4,IF(2=6,Assumptions!$B$5,Assumptions!$B$6)))*Assumptions!$B$35 | F6: =IF(1<5,0,IF(1=5,Assumptions!$B$4,IF(1=6,Assumptions!$B$5,Assumptions!$B$6)))*Assumptions!$B$36 | G6: =IF(0<5,0,IF(0=5,Assumptions!$B$4,IF(0=6,Assumptions!$B$5,Assumptions!$B$6)))*Assumptions!$B$37 | H6: =IF(-1<5,0,IF(-1=5,Assumptions!$B$4,IF(-1=6,Assumptions!$B$5,Assumptions!$B$6)))*Assumptions!$B$38 | J6: =B6+SUM(C6:H6) | K6: =J6*Assumptions!$B$3 | L6: =J6-K6
A7: 2031 | B7: 3500 | C7: 0 | D7: =IF(4<5,0,IF(4=5,Assumptions!$B$4,IF(4=6,Assumptions!$B$5,Assumptions!$B$6)))*Assumptions!$B$34 | E7: =IF(3<5,0,IF(3=5,Assumptions!$B$4,IF(3=6,Assumptions!$B$5,Assumptions!$B$6)))*Assumptions!$B$35 | F7: =IF(2<5,0,IF(2=5,Assumptions!$B$4,IF(2=6,Assumptions!$B$5,Assumptions!$B$6)))*Assumptions!$B$36 | G7: =IF(1<5,0,IF(1=5,Assumptions!$B$4,IF(1=6,Assumptions!$B$5,Assumptions!$B$6)))*Assumptions!$B$37 | H7: =IF(0<5,0,IF(0=5,Assumptions!$B$4,IF(0=6,Assumptions!$B$5,Assumptions!$B$6)))*Assumptions!$B$38 | J7: =B7+SUM(C7:H7) | K7: =J7*Assumptions!$B$3 | L7: =J7-K7
A8: 2032 | B8: 10500 | C8: 0 | D8: =IF(5<5,0,IF(5=5,Assumptions!$B$4,IF(5=6,Assumptions!$B$5,Assumptions!$B$6)))*Assumptions!$B$34 | E8: =IF(4<5,0,IF(4=5,Assumptions!$B$4,IF(4=6,Assumptions!$B$5,Assumptions!$B$6)))*Assumptions!$B$35 | F8: =IF(3<5,0,IF(3=5,Assumptions!$B$4,IF(3=6,Assumptions!$B$5,Assumptions!$B$6)))*Assumptions!$B$36 | G8: =IF(2<5,0,IF(2=5,Assumptions!$B$4,IF(2=6,Assumptions!$B$5,Assumptions!$B$6)))*Assumptions!$B$37 | H8: =IF(1<5,0,IF(1=5,Assumptions!$B$4,IF(1=6,Assumptions!$B$5,Assumptions!$B$6)))*Assumptions!$B$38 | J8: =B8+SUM(C8:H8) | K8: =J8*Assumptions!$B$3 | L8: =J8-K8
A9: 2033 | B9: =Assumptions!$B$140 | C9: 0 | D9: =IF(6<5,0,IF(6=5,Assumptions!$B$4,IF(6=6,Assumptions!$B$5,Assumptions!$B$6)))*Assumptions!$B$34 | E9: =IF(5<5,0,IF(5=5,Assumptions!$B$4,IF(5=6,Assumptions!$B$5,Assumptions!$B$6)))*Assumptions!$B$35 | F9: =IF(4<5,0,IF(4=5,Assumptions!$B$4,IF(4=6,Assumptions!$B$5,Assumptions!$B$6)))*Assumptions!$B$36 | G9: =IF(3<5,0,IF(3=5,Assumptions!$B$4,IF(3=6,Assumptions!$B$5,Assumptions!$B$6)))*Assumptions!$B$37 | H9: =IF(2<5,0,IF(2=5,Assumptions!$B$4,IF(2=6,Assumptions!$B$5,Assumptions!$B$6)))*Assumptions!$B$38 | J9: =B9+SUM(C9:H9) | K9: =J9*Assumptions!$B$3 | L9: =J9-K9
A10: 2034 | B10: =Assumptions!$B$140 | C10: 0 | D10: =IF(7<5,0,IF(7=5,Assumptions!$B$4,IF(7=6,Assumptions!$B$5,Assumptions!$B$6)))*Assumptions!$B$34 | E10: =IF(6<5,0,IF(6=5,Assumptions!$B$4,IF(6=6,Assumptions!$B$5,Assumptions!$B$6)))*Assumptions!$B$35 | F10: =IF(5<5,0,IF(5=5,Assumptions!$B$4,IF(5=6,Assumptions!$B$5,Assumptions!$B$6)))*Assumptions!$B$36 | G10: =IF(4<5,0,IF(4=5,Assumptions!$B$4,IF(4=6,Assumptions!$B$5,Assumptions!$B$6)))*Assumptions!$B$37 | H10: =IF(3<5,0,IF(3=5,Assumptions!$B$4,IF(3=6,Assumptions!$B$5,Assumptions!$B$6)))*Assumptions!$B$38 | J10: =B10+SUM(C10:H10) | K10: =J10*Assumptions!$B$3 | L10: =J10-K10
A11: 2035 | B11: =Assumptions!$B$140 | C11: 0 | D11: =IF(8<5,0,IF(8=5,Assumptions!$B$4,IF(8=6,Assumptions!$B$5,Assumptions!$B$6)))*Assumptions!$B$34 | E11: =IF(7<5,0,IF(7=5,Assumptions!$B$4,IF(7=6,Assumptions!$B$5,Assumptions!$B$6)))*Assumptions!$B$35 | F11: =IF(6<5,0,IF(6=5,Assumptions!$B$4,IF(6=6,Assumptions!$B$5,Assumptions!$B$6)))*Assumptions!$B$36 | G11: =IF(5<5,0,IF(5=5,Assumptions!$B$4,IF(5=6,Assumptions!$B$5,Assumptions!$B$6)))*Assumptions!$B$37 | H11: =IF(4<5,0,IF(4=5,Assumptions!$B$4,IF(4=6,Assumptions!$B$5,Assumptions!$B$6)))*Assumptions!$B$38 | J11: =B11+SUM(C11:H11) | K11: =J11*Assumptions!$B$3 | L11: =J11-K11
A12: 2036 | B12: =Assumptions!$B$140 | C12: 0 | D12: =IF(9<5,0,IF(9=5,Assumptions!$B$4,IF(9=6,Assumptions!$B$5,Assumptions!$B$6)))*Assumptions!$B$34 | E12: =IF(8<5,0,IF(8=5,Assumptions!$B$4,IF(8=6,Assumptions!$B$5,Assumptions!$B$6)))*Assumptions!$B$35 | F12: =IF(7<5,0,IF(7=5,Assumptions!$B$4,IF(7=6,Assumptions!$B$5,Assumptions!$B$6)))*Assumptions!$B$36 | G12: =IF(6<5,0,IF(6=5,Assumptions!$B$4,IF(6=6,Assumptions!$B$5,Assumptions!$B$6)))*Assumptions!$B$37 | H12: =IF(5<5,0,IF(5=5,Assumptions!$B$4,IF(5=6,Assumptions!$B$5,Assumptions!$B$6)))*Assumptions!$B$38 | J12: =B12+SUM(C12:H12) | K12: =J12*Assumptions!$B$3 | L12: =J12-K12
A13: 2037 | B13: =Assumptions!$B$140 | C13: 0 | D13: =IF(10<5,0,IF(10=5,Assumptions!$B$4,IF(10=6,Assumptions!$B$5,Assumptions!$B$6)))*Assumptions!$B$34 | E13: =IF(9<5,0,IF(9=5,Assumptions!$B$4,IF(9=6,Assumptions!$B$5,Assumptions!$B$6)))*Assumptions!$B$35 | F13: =IF(8<5,0,IF(8=5,Assumptions!$B$4,IF(8=6,Assumptions!$B$5,Assumptions!$B$6)))*Assumptions!$B$36 | G13: =IF(7<5,0,IF(7=5,Assumptions!$B$4,IF(7=6,Assumptions!$B$5,Assumptions!$B$6)))*Assumptions!$B$37 | H13: =IF(6<5,0,IF(6=5,Assumptions!$B$4,IF(6=6,Assumptions!$B$5,Assumptions!$B$6)))*Assumptions!$B$38 | J13: =B13+SUM(C13:H13) | K13: =J13*Assumptions!$B$3 | L13: =J13-K13
A14: 2038 | B14: =Assumptions!$B$140 | C14: 0 | D14: =IF(11<5,0,IF(11=5,Assumptions!$B$4,IF(11=6,Assumptions!$B$5,Assumptions!$B$6)))*Assumptions!$B$34 | E14: =IF(10<5,0,IF(10=5,Assumptions!$B$4,IF(10=6,Assumptions!$B$5,Assumptions!$B$6)))*Assumptions!$B$35 | F14: =IF(9<5,0,IF(9=5,Assumptions!$B$4,IF(9=6,Assumptions!$B$5,Assumptions!$B$6)))*Assumptions!$B$36 | G14: =IF(8<5,0,IF(8=5,Assumptions!$B$4,IF(8=6,Assumptions!$B$5,Assumptions!$B$6)))*Assumptions!$B$37 | H14: =IF(7<5,0,IF(7=5,Assumptions!$B$4,IF(7=6,Assumptions!$B$5,Assumptions!$B$6)))*Assumptions!$B$38 | J14: =B14+SUM(C14:H14) | K14: =J14*Assumptions!$B$3 | L14: =J14-K14

Sheet Revenue
A1: Year | B1: Net Poles | C1: Pole Revenue (MXN) | D1: Carbon Credits (0, external) | E1: Nursery Revenue (MXN) | F1: Total Revenue (MXN) | G1: Total Revenue (USD) | H1: Leased Revenue | I1: Own Revenue
A2: 2026 | B2: =Production!L2 | C2: =B2*Assumptions!$B$2 | D2: 0 | E2: 0 | F2: =SUM(C2:E2) | G2: =F2/Assumptions!$B$8 | H2: =(Production!G2+Production!H2)*(1-Assumptions!$B$3)*Assumptions!$B$2 | I2: =F2-H2
A3: 2027 | B3: =Production!L3 | C3: =B3*Assumptions!$B$2 | D3: 0 | E3: 0 | F3: =SUM(C3:E3) | G3: =F3/Assumptions!$B$8 | H3: =(Production!G3+Production!H3)*(1-Assumptions!$B$3)*Assumptions!$B$2 | I3: =F3-H3
A4: 2028 | B4: =Production!L4 | C4: =B4*Assumptions!$B$2 | D4: 0 | E4: 0 | F4: =SUM(C4:E4) | G4: =F4/Assumptions!$B$8 | H4: =(Production!G4+Production!H4)*(1-Assumptions!$B$3)*Assumptions!$B$2 | I4: =F4-H4
A5: 2029 | B5: =Production!L5 | C5: =B5*Assumptions!$B$2 | D5: 0 | E5: 0 | F5: =SUM(C5:E5) | G5: =F5/Assumptions!$B$8 | H5: =(Production!G5+Production!H5)*(1-Assumptions!$B$3)*Assumptions!$B$2 | I5: =F5-H5
A6: 2030 | B6: =Production!L6 | C6: =B6*Assumptions!$B$2 | D6: 0 | E6: =(A6-Assumptions!$B$151+1)*Assumptions!$B$150*Assumptions!$B$17 | F6: =SUM(C6:E6) | G6: =F6/Assumptions!$B$8 | H6: =(Production!G6+Production!H6)*(1-Assumptions!$B$3)*Assumptions!$B$2 | I6: =F6-H6
A7: 2031 | B7: =Production!L7 | C7: =B7*Assumptions!$B$2 | D7: 0 | E7: =(A7-Assumptions!$B$151+1)*Assumptions!$B$150*Assumptions!$B$17 | F7: =SUM(C7:E7) | G7: =F7/Assumptions!$B$8 | H7: =(Production!G7+Production!H7)*(1-Assumptions!$B$3)*Assumptions!$B$2 | I7: =F7-H7
A8: 2032 | B8: =Production!L8 | C8: =B8*Assumptions!$B$2 | D8: 0 | E8: =(A8-Assumptions!$B$151+1)*Assumptions!$B$150*Assumptions!$B$17 | F8: =SUM(C8:E8) | G8: =F8/Assumptions!$B$8 | H8: =(Production!G8+Production!H8)*(1-Assumptions!$B$3)*Assumptions!$B$2 | I8: =F8-H8
A9: 2033 | B9: =Production!L9 | C9: =B9*Assumptions!$B$2 | D9: 0 | E9: =(A9-Assumptions!$B$151+1)*Assumptions!$B$150*Assumptions!$B$17 | F9: =SUM(C9:E9) | G9: =F9/Assumptions!$B$8 | H9: =(Production!G9+Production!H9)*(1-Assumptions!$B$3)*Assumptions!$B$2 | I9: =F9-H9
A10: 2034 | B10: =Production!L10 | C10: =B10*Assumptions!$B$2 | D10: 0 | E10: =(A10-Assumptions!$B$151+1)*Assumptions!$B$150*Assumptions!$B$17 | F10: =SUM(C10:E10) | G10: =F10/Assumptions!$B$8 | H10: =(Production!G10+Production!H10)*(1-Assumptions!$B$3)*Assumptions!$B$2 | I10: =F10-H10
A11: 2035 | B11: =Production!L11 | C11: =B11*Assumptions!$B$2 | D11: 0 | E11: =(A11-Assumptions!$B$151+1)*Assumptions!$B$150*Assumptions!$B$17 | F11: =SUM(C11:E11) | G11: =F11/Assumptions!$B$8 | H11: =(Production!G11+Production!H11)*(1-Assumptions!$B$3)*Assumptions!$B$2 | I11: =F11-H11
A12: 2036 | B12: =Production!L12 | C12: =B12*Assumptions!$B$2 | D12: 0 | E12: =(A12-Assumptions!$B$151+1)*Assumptions!$B$150*Assumptions!$B$17 | F12: =SUM(C12:E12) | G12: =F12/Assumptions!$B$8 | H12: =(Production!G12+Production!H12)*(1-Assumptions!$B$3)*Assumptions!$B$2 | I12: =F12-H12
A13: 2037 | B13: =Production!L13 | C13: =B13*Assumptions!$B$2 | D13: 0 | E13: =(A13-Assumptions!$B$151+1)*Assumptions!$B$150*Assumptions!$B$17 | F13: =SUM(C13:E13) | G13: =F13/Assumptions!$B$8 | H13: =(Production!G13+Production!H13)*(1-Assumptions!$B$3)*Assumptions!$B$2 | I13: =F13-H13
A14: 2038 | B14: =Production!L14 | C14: =B14*Assumptions!$B$2 | D14: 0 | E14: =(A14-Assumptions!$B$151+1)*Assumptions!$B$150*Assumptions!$B$17 | F14: =SUM(C14:E14) | G14: =F14/Assumptions!$B$8 | H14: =(Production!G14+Production!H14)*(1-Assumptions!$B$3)*Assumptions!$B$2 | I14: =F14-H14

Sheet Expenses
A1: Year | B1: Planting Costs | C1: Fixed Ops (Workers) | D1: Mgmt Salaries | E1: Consumables | F1: SG&A | G1: Nursery Labor | H1: Tractor Rental | I1: Logistics | J1: Consulting & Tech | K1: Sub-Total (excl Lease) | L1: Pool Liquids | M1: Lease Payments | N1: Total Expenses | O1: External Clearing
A2: 2026 | B2: =Assumptions!$B$134*Assumptions!$B$18 | C2: =CEILING(Assumptions!C33/Assumptions!$B$77,1)*Assumptions!$B$76 | D2: =Assumptions!$B$114*VLOOKUP(A2,Assumptions!$A$154:$B$166,2,FALSE)*12 | E2: =C2*0.1 | F2: =Assumptions!$B$108 | G2: 0 | H2: 0 | I2: =Production!L2*Assumptions!$B$129 | J2: 0 | K2: =SUM(B2:J2)+L2+O2 | L2: 0 | M2: 0 | N2: =K2+M2 | O2: =20*Assumptions!$B$82
A3: 2027 | B3: =Assumptions!B34*(Assumptions!$B$89+Assumptions!$B$19*Assumptions!$B$17) | C3: =CEILING(Assumptions!C34/Assumptions!$B$77,1)*Assumptions!$B$76 | D3: =Assumptions!$B$114*VLOOKUP(A3,Assumptions!$A$154:$B$166,2,FALSE)*12 | E3: =C3*0.1 | F3: =Assumptions!$B$109 | G3: 0 | H3: 0 | I3: =Production!L3*Assumptions!$B$129 | J3: 0 | K3: =SUM(B3:J3)+L3+O3 | L3: =CEILING(Production!L3/Assumptions!$B$95,1)*Assumptions!$B$97 | M3: 0 | N3: =K3+M3 | O3: =Assumptions!B34*Assumptions!$B$82
A4: 2028 | B4: =Assumptions!B35*(Assumptions!$B$89+Assumptions!$B$19*Assumptions!$B$17) | C4: =CEILING(Assumptions!C35/Assumptions!$B$77,1)*Assumptions!$B$76 | D4: =Assumptions!$B$114*VLOOKUP(A4,Assumptions!$A$154:$B$166,2,FALSE)*12 | E4: =C4*0.1 | F4: =Assumptions!$B$110 | G4: 0 | H4: 0 | I4: =Production!L4*Assumptions!$B$129 | J4: =IF(A4>=Assumptions!$B$121,Assumptions!$B$120,0) | K4: =SUM(B4:J4)+L4+O4 | L4: =CEILING(Production!L4/Assumptions!$B$95,1)*Assumptions!$B$97 | M4: 0 | N4: =K4+M4 | O4: =Assumptions!B35*Assumptions!$B$82
A5: 2029 | B5: =Assumptions!B36*(Assumptions!$B$89+Assumptions!$B$19*Assumptions!$B$18) | C5: =CEILING(Assumptions!C36/Assumptions!$B$77,1)*Assumptions!$B$76 | D5: =Assumptions!$B$114*VLOOKUP(A5,Assumptions!$A$154:$B$166,2,FALSE)*12 | E5: =C5*0.1 | F5: =F4*(1+Assumptions!$B$111) | G5: =IF(A5>=Assumptions!$B$119,Assumptions!$B$118,0) | H5: 0 | I5: =Production!L5*Assumptions!$B$129 | J5: =IF(A5>=Assumptions!$B$121,Assumptions!$B$120,0) | K5: =SUM(B5:J5)+L5+O5 | L5: =CEILING(Production!L5/Assumptions!$B$95,1)*Assumptions!$B$97 | M5: 0 | N5: =K5+M5 | O5: =Assumptions!B36*Assumptions!$B$82
A6: 2030 | B6: =Assumptions!B37*(Assumptions!$B$89+Assumptions!$B$19*Assumptions!$B$18) | C6: =CEILING(Assumptions!C37/Assumptions!$B$77,1)*Assumptions!$B$76 | D6: =Assumptions!$B$114*VLOOKUP(A6,Assumptions!$A$154:$B$166,2,FALSE)*12 | E6: =C6*0.1 | F6: =F5*(1+Assumptions!$B$111) | G6: =IF(A6>=Assumptions!$B$119,Assumptions!$B$118,0) | H6: =IF(A6>=Assumptions!$B$128,Assumptions!C37*Assumptions!$B$127,0) | I6: =Production!L6*Assumptions!$B$129 | J6: =IF(A6>=Assumptions!$B$121,Assumptions!$B$120,0)+IF(A6>=Assumptions!$B$123,Assumptions!$B$122,0) | K6: =SUM(B6:J6)+L6+O6 | L6: =CEILING(Production!L6/Assumptions!$B$95,1)*Assumptions!$B$97 | M6: 0 | N6: =K6+M6 | O6: =Assumptions!B37*Assumptions!$B$82
A7: 2031 | B7: =Assumptions!B38*(Assumptions!$B$89+Assumptions!$B$19*Assumptions!$B$18) | C7: =CEILING(Assumptions!C38/Assumptions!$B$77,1)*Assumptions!$B$76 | D7: =Assumptions!$B$114*VLOOKUP(A7,Assumptions!$A$154:$B$166,2,FALSE)*12 | E7: =C7*0.1 | F7: =F6*(1+Assumptions!$B$111) | G7: =IF(A7>=Assumptions!$B$119,Assumptions!$B$118,0) | H7: =IF(A7>=Assumptions!$B$128,Assumptions!C38*Assumptions!$B$127,0) | I7: =Production!L7*Assumptions!$B$129 | J7: =IF(A7>=Assumptions!$B$121,Assumptions!$B$120,0)+IF(A7>=Assumptions!$B$123,Assumptions!$B$122,0) | K7: =SUM(B7:J7)+L7+O7 | L7: =CEILING(Production!L7/Assumptions!$B$95,1)*Assumptions!$B$97 | M7: 0 | N7: =K7+M7 | O7: =Assumptions!B38*Assumptions!$B$82
A8: 2032 | B8: 0 | C8: =CEILING(Assumptions!C39/Assumptions!$B$77,1)*Assumptions!$B$76 | D8: =Assumptions!$B$114*VLOOKUP(A8,Assumptions!$A$154:$B$166,2,FALSE)*12 | E8: =C8*0.1 | F8: =F7*(1+Assumptions!$B$111) | G8: =IF(A8>=Assumptions!$B$119,Assumptions!$B$118,0) | H8: =IF(A8>=Assumptions!$B$128,Assumptions!C39*Assumptions!$B$127,0) | I8: =Production!L8*Assumptions!$B$129 | J8: =IF(A8>=Assumptions!$B$121,Assumptions!$B$120,0)+IF(A8>=Assumptions!$B$123,Assumptions!$B$122,0) | K8: =SUM(B8:J8)+L8+O8 | L8: =CEILING(Production!L8/Assumptions!$B$95,1)*Assumptions!$B$97 | M8: 0 | N8: =K8+M8 | O8: 0
A9: 2033 | B9: 0 | C9: =CEILING(Assumptions!C40/Assumptions!$B$77,1)*Assumptions!$B$76 | D9: =Assumptions!$B$114*VLOOKUP(A9,Assumptions!$A$154:$B$166,2,FALSE)*12 | E9: =C9*0.1 | F9: =F8*(1+Assumptions!$B$111) | G9: =IF(A9>=Assumptions!$B$119,Assumptions!$B$118,0) | H9: =IF(A9>=Assumptions!$B$128,Assumptions!C40*Assumptions!$B$127,0) | I9: =Production!L9*Assumptions!$B$129 | J9: =IF(A9>=Assumptions!$B$121,Assumptions!$B$120,0)+IF(A9>=Assumptions!$B$123,Assumptions!$B$122,0) | K9: =SUM(B9:J9)+L9+O9 | L9: =CEILING(Production!L9/Assumptions!$B$95,1)*Assumptions!$B$97 | M9: 0 | N9: =K9+M9 | O9: 0
A10: 2034 | B10: 0 | C10: =CEILING(Assumptions!C40/Assumptions!$B$77,1)*Assumptions!$B$76 | D10: =Assumptions!$B$114*VLOOKUP(A10,Assumptions!$A$154:$B$166,2,FALSE)*12 | E10: =C10*0.1 | F10: =F9*(1+Assumptions!$B$111) | G10: =IF(A10>=Assumptions!$B$119,Assumptions!$B$118,0) | H10: =IF(A10>=Assumptions!$B$128,Assumptions!C40*Assumptions!$B$127,0) | I10: =Production!L10*Assumptions!$B$129 | J10: =IF(A10>=Assumptions!$B$121,Assumptions!$B$120,0)+IF(A10>=Assumptions!$B$123,Assumptions!$B$122,0) | K10: =SUM(B10:J10)+L10+O10 | L10: =CEILING(Production!L10/Assumptions!$B$95,1)*Assumptions!$B$97 | M10: 0 | N10: =K10+M10 | O10: 0
A11: 2035 | B11: 0 | C11: =CEILING(Assumptions!C40/Assumptions!$B$77,1)*Assumptions!$B$76 | D11: =Assumptions!$B$114*VLOOKUP(A11,Assumptions!$A$154:$B$166,2,FALSE)*12 | E11: =C11*0.1 | F11: =F10*(1+Assumptions!$B$111) | G11: =IF(A11>=Assumptions!$B$119,Assumptions!$B$118,0) | H11: =IF(A11>=Assumptions!$B$128,Assumptions!C40*Assumptions!$B$127,0) | I11: =Production!L11*Assumptions!$B$129 | J11: =IF(A11>=Assumptions!$B$121,Assumptions!$B$120,0)+IF(A11>=Assumptions!$B$123,Assumptions!$B$122,0) | K11: =SUM(B11:J11)+L11+O11 | L11: =CEILING(Production!L11/Assumptions!$B$95,1)*Assumptions!$B$97 | M11: =Assumptions!$B$144*MAX(0,((Production!G11+Production!H11)*(1-Assumptions!$B$3)*Assumptions!$B$2-K11*((IF(A11-2030>=5,Assumptions!$B$37,0)+IF(A11-2031>=5,Assumptions!$B$38,0))/Assumptions!C40))) | N11: =K11+M11 | O11: 0
A12: 2036 | B12: 0 | C12: =CEILING(Assumptions!C40/Assumptions!$B$77,1)*Assumptions!$B$76 | D12: =Assumptions!$B$114*VLOOKUP(A12,Assumptions!$A$154:$B$166,2,FALSE)*12 | E12: =C12*0.1 | F12: =F11*(1+Assumptions!$B$111) | G12: =IF(A12>=Assumptions!$B$119,Assumptions!$B$118,0) | H12: =IF(A12>=Assumptions!$B$128,Assumptions!C40*Assumptions!$B$127,0) | I12: =Production!L12*Assumptions!$B$129 | J12: =IF(A12>=Assumptions!$B$121,Assumptions!$B$120,0)+IF(A12>=Assumptions!$B$123,Assumptions!$B$122,0) | K12: =SUM(B12:J12)+L12+O12 | L12: =CEILING(Production!L12/Assumptions!$B$95,1)*Assumptions!$B$97 | M12: =Assumptions!$B$144*MAX(0,((Production!G12+Production!H12)*(1-Assumptions!$B$3)*Assumptions!$B$2-K12*((IF(A12-2030>=5,Assumptions!$B$37,0)+IF(A12-2031>=5,Assumptions!$B$38,0))/Assumptions!C40))) | N12: =K12+M12 | O12: 0
A13: 2037 | B13: 0 | C13: =CEILING(Assumptions!C40/Assumptions!$B$77,1)*Assumptions!$B$76 | D13: =Assumptions!$B$114*VLOOKUP(A13,Assumptions!$A$154:$B$166,2,FALSE)*12 | E13: =C13*0.1 | F13: =F12*(1+Assumptions!$B$111) | G13: =IF(A13>=Assumptions!$B$119,Assumptions!$B$118,0) | H13: =IF(A13>=Assumptions!$B$128,Assumptions!C40*Assumptions!$B$127,0) | I13: =Production!L13*Assumptions!$B$129 | J13: =IF(A13>=Assumptions!$B$121,Assumptions!$B$120,0)+IF(A13>=Assumptions!$B$123,Assumptions!$B$122,0) | K13: =SUM(B13:J13)+L13+O13 | L13: =CEILING(Production!L13/Assumptions!$B$95,1)*Assumptions!$B$97 | M13: =Assumptions!$B$144*MAX(0,((Production!G13+Production!H13)*(1-Assumptions!$B$3)*Assumptions!$B$2-K13*((IF(A13-2030>=5,Assumptions!$B$37,0)+IF(A13-2031>=5,Assumptions!$B$38,0))/Assumptions!C40))) | N13: =K13+M13 | O13: 0
A14: 2038 | B14: 0 | C14: =CEILING(Assumptions!C40/Assumptions!$B$77,1)*Assumptions!$B$76 | D14: =Assumptions!$B$114*VLOOKUP(A14,Assumptions!$A$154:$B$166,2,FALSE)*12 | E14: =C14*0.1 | F14: =F13*(1+Assumptions!$B$111) | G14: =IF(A14>=Assumptions!$B$119,Assumptions!$B$118,0) | H14: =IF(A14>=Assumptions!$B$128,Assumptions!C40*Assumptions!$B$127,0) | I14: =Production!L14*Assumptions!$B$129 | J14: =IF(A14>=Assumptions!$B$121,Assumptions!$B$120,0)+IF(A14>=Assumptions!$B$123,Assumptions!$B$122,0) | K14: =SUM(B14:J14)+L14+O14 | L14: =CEILING(Production!L14/Assumptions!$B$95,1)*Assumptions!$B$97 | M14: =Assumptions!$B$144*MAX(0,((Production!G14+Production!H14)*(1-Assumptions!$B$3)*Assumptions!$B$2-K14*((IF(A14-2030>=5,Assumptions!$B$37,0)+IF(A14-2031>=5,Assumptions!$B$38,0))/Assumptions!C40))) | N14: =K14+M14 | O14: 0

Sheet Capex
A1: Year | B1: Total Capex (MXN) | C1: Fixed Items | D1: New Pools | E1: Bodegas | F1: Infra Capex
A2: 2026 | B2: =C2+F2 | C2: =SUMIF(Assumptions!C45:C57,A2,Assumptions!B45:B57) | D2: 0 | E2: =IF(Assumptions!C33>=10,1,0) | F2: =E2*Assumptions!$B$102
A3: 2027 | B3: =C3+F3 | C3: =SUMIF(Assumptions!C45:C57,A3,Assumptions!B45:B57) | D3: =MAX(0,CEILING(Production!L3/Assumptions!$B$95,1)-SUM(D2:D2)) | E3: =IF(OR(A3=Assumptions!$B$170,A3=Assumptions!$B$171),1,0) | F3: =D3*Assumptions!$B$96+E3*Assumptions!$B$102
A4: 2028 | B4: =C4+F4 | C4: =SUMIF(Assumptions!C45:C57,A4,Assumptions!B45:B57) | D4: =MAX(0,CEILING(Production!L4/Assumptions!$B$95,1)-SUM(D2:D3)) | E4: =IF(OR(A4=Assumptions!$B$170,A4=Assumptions!$B$171),1,0) | F4: =D4*Assumptions!$B$96+E4*Assumptions!$B$102
A5: 2029 | B5: =C5+F5 | C5: =SUMIF(Assumptions!C45:C57,A5,Assumptions!B45:B57) | D5: =MAX(0,CEILING(Production!L5/Assumptions!$B$95,1)-SUM(D2:D4)) | E5: =IF(OR(A5=Assumptions!$B$170,A5=Assumptions!$B$171),1,0) | F5: =D5*Assumptions!$B$96+E5*Assumptions!$B$102
A6: 2030 | B6: =C6+F6 | C6: =SUMIF(Assumptions!C45:C57,A6,Assumptions!B45:B57) | D6: =MAX(0,CEILING(Production!L6/Assumptions!$B$95,1)-SUM(D2:D5)) | E6: =IF(OR(A6=Assumptions!$B$170,A6=Assumptions!$B$171),1,0) | F6: =D6*Assumptions!$B$96+E6*Assumptions!$B$102
A7: 2031 | B7: =C7+F7 | C7: =SUMIF(Assumptions!C45:C57,A7,Assumptions!B45:B57) | D7: =MAX(0,CEILING(Production!L7/Assumptions!$B$95,1)-SUM(D2:D6)) | E7: =IF(OR(A7=Assumptions!$B$170,A7=Assumptions!$B$171),1,0) | F7: =D7*Assumptions!$B$96+E7*Assumptions!$B$102
A8: 2032 | B8: =C8+F8 | C8: =SUMIF(Assumptions!C45:C57,A8,Assumptions!B45:B57) | D8: =MAX(0,CEILING(Production!L8/Assumptions!$B$95,1)-SUM(D2:D7)) | E8: =IF(OR(A8=Assumptions!$B$170,A8=Assumptions!$B$171),1,0) | F8: =D8*Assumptions!$B$96+E8*Assumptions!$B$102
A9: 2033 | B9: =C9+F9 | C9: =SUMIF(Assumptions!C45:C57,A9,Assumptions!B45:B57) | D9: =MAX(0,CEILING(Production!L9/Assumptions!$B$95,1)-SUM(D2:D8)) | E9: =IF(OR(A9=Assumptions!$B$170,A9=Assumptions!$B$171),1,0) | F9: =D9*Assumptions!$B$96+E9*Assumptions!$B$102
A10: 2034 | B10: =C10+F10 | C10: =SUMIF(Assumptions!C45:C57,A10,Assumptions!B45:B57) | D10: =MAX(0,CEILING(Production!L10/Assumptions!$B$95,1)-SUM(D2:D9)) | E10: =IF(A10=Assumptions!$B$104,1,0) | F10: =D10*Assumptions!$B$96+E10*Assumptions!$B$103
A11: 2035 | B11: =C11+F11 | C11: =SUMIF(Assumptions!C45:C57,A11,Assumptions!B45:B57) | D11: =MAX(0,CEILING(Production!L11/Assumptions!$B$95,1)-SUM(D2:D10)) | E11: =IF(OR(A11=Assumptions!$B$170,A11=Assumptions!$B$171),1,0) | F11: =D11*Assumptions!$B$96+E11*Assumptions!$B$102
A12: 2036 | B12: =C12+F12 | C12: =SUMIF(Assumptions!C45:C57,A12,Assumptions!B45:B57) | D12: =MAX(0,CEILING(Production!L12/Assumptions!$B$95,1)-SUM(D2:D11)) | E12: =IF(OR(A12=Assumptions!$B$170,A12=Assumptions!$B$171),1,0) | F12: =D12*Assumptions!$B$96+E12*Assumptions!$B$102
A13: 2037 | B13: =C13+F13 | C13: =SUMIF(Assumptions!C45:C57,A13,Assumptions!B45:B57) | D13: =MAX(0,CEILING(Production!L13/Assumptions!$B$95,1)-SUM(D2:D12)) | E13: =IF(OR(A13=Assumptions!$B$170,A13=Assumptions!$B$171),1,0) | F13: =D13*Assumptions!$B$96+E13*Assumptions!$B$102
A14: 2038 | B14: =C14+F14 | C14: =SUMIF(Assumptions!C45:C57,A14,Assumptions!B45:B57) | D14: =MAX(0,CEILING(Production!L14/Assumptions!$B$95,1)-SUM(D2:D13)) | E14: =IF(OR(A14=Assumptions!$B$170,A14=Assumptions!$B$171),1,0) | F14: =D14*Assumptions!$B$96+E14*Assumptions!$B$102

Sheet Cash Flow
A1: Year | B1: Revenue | C1: OpEx | D1: Capex | E1: Funding | F1: Net Cash Flow | G1: Cumulative Cash | H1: Status
A2: 2026 | B2: =Revenue!F2 | C2: =Expenses!N2 | D2: =Capex!B2 | E2: =IF(A2=2026,Assumptions!$B$9,0)+IF(A2=Assumptions!$B$11,Assumptions!$B$10,0) | F2: =B2-C2-D2+E2 | G2: =F2 | H2: =IF(G2<0,"NEGATIVE","OK")
A3: 2027 | B3: =Revenue!F3 | C3: =Expenses!N3 | D3: =Capex!B3 | E3: =IF(A3=2026,Assumptions!$B$9,0)+IF(A3=Assumptions!$B$11,Assumptions!$B$10,0) | F3: =B3-C3-D3+E3 | G3: =G2+F3 | H3: =IF(G3<0,"NEGATIVE","OK")
A4: 2028 | B4: =Revenue!F4 | C4: =Expenses!N4 | D4: =Capex!B4 | E4: =IF(A4=2026,Assumptions!$B$9,0)+IF(A4=Assumptions!$B$11,Assumptions!$B$10,0) | F4: =B4-C4-D4+E4 | G4: =G3+F4 | H4: =IF(G4<0,"NEGATIVE","OK")
A5: 2029 | B5: =Revenue!F5 | C5: =Expenses!N5 | D5: =Capex!B5 | E5: =IF(A5=2026,Assumptions!$B$9,0)+IF(A5=Assumptions!$B$11,Assumptions!$B$10,0) | F5: =B5-C5-D5+E5 | G5: =G4+F5 | H5: =IF(G5<0,"NEGATIVE","OK")
A6: 2030 | B6: =Revenue!F6 | C6: =Expenses!N6 | D6: =Capex!B6 | E6: =IF(A6=2026,Assumptions!$B$9,0)+IF(A6=Assumptions!$B$11,Assumptions!$B$10,0) | F6: =B6-C6-D6+E6 | G6: =G5+F6 | H6: =IF(G6<0,"NEGATIVE","OK")
A7: 2031 | B7: =Revenue!F7 | C7: =Expenses!N7 | D7: =Capex!B7 | E7: =IF(A7=2026,Assumptions!$B$9,0)+IF(A7=Assumptions!$B$11,Assumptions!$B$10,0) | F7: =B7-C7-D7+E7 | G7: =G6+F7 | H7: =IF(G7<0,"NEGATIVE","OK")
A8: 2032 | B8: =Revenue!F8 | C8: =Expenses!N8 | D8: =Capex!B8 | E8: =IF(A8=2026,Assumptions!$B$9,0)+IF(A8=Assumptions!$B$11,Assumptions!$B$10,0) | F8: =B8-C8-D8+E8 | G8: =G7+F8 | H8: =IF(G8<0,"NEGATIVE","OK")
A9: 2033 | B9: =Revenue!F9 | C9: =Expenses!N9 | D9: =Capex!B9 | E9: =IF(A9=2026,Assumptions!$B$9,0)+IF(A9=Assumptions!$B$11,Assumptions!$B$10,0) | F9: =B9-C9-D9+E9 | G9: =G8+F9 | H9: =IF(G9<0,"NEGATIVE","OK")
A10: 2034 | B10: =Revenue!F10 | C10: =Expenses!N10 | D10: =Capex!B10 | E10: =IF(A10=2026,Assumptions!$B$9,0)+IF(A10=Assumptions!$B$11,Assumptions!$B$10,0) | F10: =B10-C10-D10+E10 | G10: =G9+F10 | H10: =IF(G10<0,"NEGATIVE","OK")
A11: 2035 | B11: =Revenue!F11 | C11: =Expenses!N11 | D11: =Capex!B11 | E11: =IF(A11=2026,Assumptions!$B$9,0)+IF(A11=Assumptions!$B$11,Assumptions!$B$10,0) | F11: =B11-C11-D11+E11 | G11: =G10+F11 | H11: =IF(G11<0,"NEGATIVE","OK")
A12: 2036 | B12: =Revenue!F12 | C12: =Expenses!N12 | D12: =Capex!B12 | E12: =IF(A12=2026,Assumptions!$B$9,0)+IF(A12=Assumptions!$B$11,Assumptions!$B$10,0) | F12: =B12-C12-D12+E12 | G12: =G11+F12 | H12: =IF(G12<0,"NEGATIVE","OK")
A13: 2037 | B13: =Revenue!F13 | C13: =Expenses!N13 | D13: =Capex!B13 | E13: =IF(A13=2026,Assumptions!$B$9,0)+IF(A13=Assumptions!$B$11,Assumptions!$B$10,0) | F13: =B13-C13-D13+E13 | G13: =G12+F13 | H13: =IF(G13<0,"NEGATIVE","OK")
A14: 2038 | B14: =Revenue!F14 | C14: =Expenses!N14 | D14: =Capex!B14 | E14: =IF(A14=2026,Assumptions!$B$9,0)+IF(A14=Assumptions!$B$11,Assumptions!$B$10,0) | F14: =B14-C14-D14+E14 | G14: =G13+F14 | H14: =IF(G14<0,"NEGATIVE","OK")

Sheet Earn-Loss
A1: Year | B1: Revenue | C1: Expenses | D1: Capex | E1: Net Income
A2: 2026 | B2: =Revenue!F2 | C2: =Expenses!N2 | D2: =Capex!B2 | E2: =B2-C2-D2
A3: 2027 | B3: =Revenue!F3 | C3: =Expenses!N3 | D3: =Capex!B3 | E3: =B3-C3-D3
A4: 2028 | B4: =Revenue!F4 | C4: =Expenses!N4 | D4: =Capex!B4 | E4: =B4-C4-D4
A5: 2029 | B5: =Revenue!F5 | C5: =Expenses!N5 | D5: =Capex!B5 | E5: =B5-C5-D5
A6: 2030 | B6: =Revenue!F6 | C6: =Expenses!N6 | D6: =Capex!B6 | E6: =B6-C6-D6
A7: 2031 | B7: =Revenue!F7 | C7: =Expenses!N7 | D7: =Capex!B7 | E7: =B7-C7-D7
A8: 2032 | B8: =Revenue!F8 | C8: =Expenses!N8 | D8: =Capex!B8 | E8: =B8-C8-D8
A9: 2033 | B9: =Revenue!F9 | C9: =Expenses!N9 | D9: =Capex!B9 | E9: =B9-C9-D9
A10: 2034 | B10: =Revenue!F10 | C10: =Expenses!N10 | D10: =Capex!B10 | E10: =B10-C10-D10
A11: 2035 | B11: =Revenue!F11 | C11: =Expenses!N11 | D11: =Capex!B11 | E11: =B11-C11-D11
A12: 2036 | B12: =Revenue!F12 | C12: =Expenses!N12 | D12: =Capex!B12 | E12: =B12-C12-D12
A13: 2037 | B13: =Revenue!F13 | C13: =Expenses!N13 | D13: =Capex!B13 | E13: =B13-C13-D13
A14: 2038 | B14: =Revenue!F14 | C14: =Expenses!N14 | D14: =Capex!B14 | E14: =B14-C14-D14

Sheet Sensitivity
A1: SENSITIVITY ANALYSIS: Revenue by Yield Scenario
A2: Year | B2: Conservative (1,000/ha) | C2: Base (2,000/ha) | D2: Optimistic (3,000/ha) | E2: Cons. Cum Profit | F2: Base Cum Profit | G2: Opt. Cum Profit
A3: 2026 | B3: =Revenue!C2*0.5+Revenue!D2+Revenue!E2 | C3: =Revenue!F2 | D3: =Revenue!C2*1.5+Revenue!D2+Revenue!E2 | E3: =B3-Expenses!N2-Capex!B2 | F3: =C3-Expenses!N2-Capex!B2 | G3: =D3-Expenses!N2-Capex!B2
A4: 2027 | B4: =Revenue!C3*0.5+Revenue!D3+Revenue!E3 | C4: =Revenue!F3 | D4: =Revenue!C3*1.5+Revenue!D3+Revenue!E3 | E4: =E3+B4-Expenses!N3-Capex!B3 | F4: =F3+C4-Expenses!N3-Capex!B3 | G4: =G3+D4-Expenses!N3-Capex!B3
A5: 2028 | B5: =Revenue!C4*0.5+Revenue!D4+Revenue!E4 | C5: =Revenue!F4 | D5: =Revenue!C4*1.5+Revenue!D4+Revenue!E4 | E5: =E4+B5-Expenses!N4-Capex!B4 | F5: =F4+C5-Expenses!N4-Capex!B4 | G5: =G4+D5-Expenses!N4-Capex!B4
A6: 2029 | B6: =Revenue!C5*0.5+Revenue!D5+Revenue!E5 | C6: =Revenue!F5 | D6: =Revenue!C5*1.5+Revenue!D5+Revenue!E5 | E6: =E5+B6-Expenses!N5-Capex!B5 | F6: =F5+C6-Expenses!N5-Capex!B5 | G6: =G5+D6-Expenses!N5-Capex!B5
A7: 2030 | B7: =Revenue!C6*0.5+Revenue!D6+Revenue!E6 | C7: =Revenue!F6 | D7: =Revenue!C6*1.5+Revenue!D6+Revenue!E6 | E7: =E6+B7-Expenses!N6-Capex!B6 | F7: =F6+C7-Expenses!N6-Capex!B6 | G7: =G6+D7-Expenses!N6-Capex!B6
A8: 2031 | B8: =Revenue!C7*0.5+Revenue!D7+Revenue!E7 | C8: =Revenue!F7 | D8: =Revenue!C7*1.5+Revenue!D7+Revenue!E7 | E8: =E7+B8-Expenses!N7-Capex!B7 | F8: =F7+C8-Expenses!N7-Capex!B7 | G8: =G7+D8-Expenses!N7-Capex!B7
A9: 2032 | B9: =Revenue!C8*0.5+Revenue!D8+Revenue!E8 | C9: =Revenue!F8 | D9: =Revenue!C8*1.5+Revenue!D8+Revenue!E8 | E9: =E8+B9-Expenses!N8-Capex!B8 | F9: =F8+C9-Expenses!N8-Capex!B8 | G9: =G8+D9-Expenses!N8-Capex!B8
A10: 2033 | B10: =Revenue!C9*0.5+Revenue!D9+Revenue!E9 | C10: =Revenue!F9 | D10: =Revenue!C9*1.5+Revenue!D9+Revenue!E9 | E10: =E9+B10-Expenses!N9-Capex!B9 | F10: =F9+C10-Expenses!N9-Capex!B9 | G10: =G9+D10-Expenses!N9-Capex!B9
A11: 2034 | B11: =Revenue!C10*0.5+Revenue!D10+Revenue!E10 | C11: =Revenue!F10 | D11: =Revenue!C10*1.5+Revenue!D10+Revenue!E10 | E11: =E10+B11-Expenses!N10-Capex!B10 | F11: =F10+C11-Expenses!N10-Capex!B10 | G11: =G10+D11-Expenses!N10-Capex!B10
A12: 2035 | B12: =Revenue!C11*0.5+Revenue!D11+Revenue!E11 | C12: =Revenue!F11 | D12: =Revenue!C11*1.5+Revenue!D11+Revenue!E11 | E12: =E11+B12-Expenses!N11-Capex!B11 | F12: =F11+C12-Expenses!N11-Capex!B11 | G12: =G11+D12-Expenses!N11-Capex!B11
A13: 2036 | B13: =Revenue!C12*0.5+Revenue!D12+Revenue!E12 | C13: =Revenue!F12 | D13: =Revenue!C12*1.5+Revenue!D12+Revenue!E12 | E13: =E12+B13-Expenses!N12-Capex!B12 | F13: =F12+C13-Expenses!N12-Capex!B12 | G13: =G12+D13-Expenses!N12-Capex!B12
A14: 2037 | B14: =Revenue!C13*0.5+Revenue!D13+Revenue!E13 | C14: =Revenue!F13 | D14: =Revenue!C13*1.5+Revenue!D13+Revenue!E13 | E14: =E13+B14-Expenses!N13-Capex!B13 | F14: =F13+C14-Expenses!N13-Capex!B13 | G14: =G13+D14-Expenses!N13-Capex!B13
A15: 2038 | B15: =Revenue!C14*0.5+Revenue!D14+Revenue!E14 | C15: =Revenue!F14 | D15: =Revenue!C14*1.5+Revenue!D14+Revenue!E14 | E15: =E14+B15-Expenses!N14-Capex!B14 | F15: =F14+C15-Expenses!N14-Capex!B14 | G15: =G14+D15-Expenses!N14-Capex!B14
